{"content": {"suites": {"0": {"status": {"total_pass": 0, "total_skip": 0, "total_xpass": 0, "total_xfail": 0, "total_rerun": 0, "total_fail": 1, "total_error": 0}, "tests": {"0": {"status": "FAIL", "message": "           TimeoutError: [WinError 10060] A connection attempt failed because the connected party did not properly respond after a period of time, or established connection failed because connected host has failed to respond\n       urllib3.exceptions.ConnectTimeoutError: (<urllib3.connection.HTTPConnection object at 0x000001CB60861A50>, 'Connection to host.docker.internal timed out. (connect timeout=None)')\n       urllib3.exceptions.MaxRetryError: HTTPConnectionPool(host='host.docker.internal', port=5102): Max retries exceeded with url: /api/v1/Orders (Caused by ConnectTimeoutError(<urllib3.connection.HTTPConnection object at 0x000001CB60861A50>, 'Connection to host.docker.internal timed out. (connect timeout=None)'))\n               requests.exceptions.ConnectTimeout: HTTPConnectionPool(host='host.docker.internal', port=5102): Max retries exceeded with url: /api/v1/Orders (Caused by ConnectTimeoutError(<urllib3.connection.HTTPConnection object at 0x000001CB60861A50>, 'Connection to host.docker.internal timed out. (connect timeout=None)'))\n", "test_name": "test_get_all_orders", "rerun": "0"}}, "suite_name": "Tests/test_ordering_api.py"}}}, "date": "March 19, 2023", "start_time": 1679207041.2892654, "total_suite": 1, "status": "FAIL", "status_list": {"pass": "0", "fail": "1", "skip": "0", "error": "0", "xpass": "0", "xfail": "0", "rerun": "0"}, "total_tests": "1"}