{"content": {"suites": {"0": {"status": {"total_pass": 1, "total_skip": 0, "total_xpass": 0, "total_xfail": 0, "total_rerun": 0, "total_fail": 8, "total_error": 0}, "tests": {"0": {"status": "PASS", "message": "", "test_name": "test_ordering_process_over_time", "rerun": "0"}, "1": {"status": "FAIL", "message": "           TimeoutError: [WinError 10060] A connection attempt failed because the connected party did not properly respond after a period of time, or established connection failed because connected host has failed to respond\n       urllib3.exceptions.ConnectTimeoutError: (<urllib3.connection.HTTPConnection object at 0x0000019F437168F0>, 'Connection to host.docker.internal timed out. (connect timeout=None)')\n       urllib3.exceptions.MaxRetryError: HTTPConnectionPool(host='host.docker.internal', port=5102): Max retries exceeded with url: /api/v1/Orders/ship (Caused by ConnectTimeoutError(<urllib3.connection.HTTPConnection object at 0x0000019F437168F0>, 'Connection to host.docker.internal timed out. (connect timeout=None)'))\n               requests.exceptions.ConnectTimeout: HTTPConnectionPool(host='host.docker.internal', port=5102): Max retries exceeded with url: /api/v1/Orders/ship (Caused by ConnectTimeoutError(<urllib3.connection.HTTPConnection object at 0x0000019F437168F0>, 'Connection to host.docker.internal timed out. (connect timeout=None)'))\n", "test_name": "test_ordering_service_after_crash", "rerun": "0"}, "2": {"status": "FAIL", "message": "           TimeoutError: [WinError 10060] A connection attempt failed because the connected party did not properly respond after a period of time, or established connection failed because connected host has failed to respond\n       urllib3.exceptions.ConnectTimeoutError: (<urllib3.connection.HTTPConnection object at 0x0000019F4397F9D0>, 'Connection to host.docker.internal timed out. (connect timeout=None)')\n       urllib3.exceptions.MaxRetryError: HTTPConnectionPool(host='host.docker.internal', port=5102): Max retries exceeded with url: /api/v1/Orders/cancel (Caused by ConnectTimeoutError(<urllib3.connection.HTTPConnection object at 0x0000019F4397F9D0>, 'Connection to host.docker.internal timed out. (connect timeout=None)'))\n               requests.exceptions.ConnectTimeout: HTTPConnectionPool(host='host.docker.internal', port=5102): Max retries exceeded with url: /api/v1/Orders/cancel (Caused by ConnectTimeoutError(<urllib3.connection.HTTPConnection object at 0x0000019F4397F9D0>, 'Connection to host.docker.internal timed out. (connect timeout=None)'))\n", "test_name": "test_cancel_other_user_order", "rerun": "0"}, "3": {"status": "FAIL", "message": "           TimeoutError: [WinError 10060] A connection attempt failed because the connected party did not properly respond after a period of time, or established connection failed because connected host has failed to respond\n       urllib3.exceptions.ConnectTimeoutError: (<urllib3.connection.HTTPConnection object at 0x0000019F43C47E50>, 'Connection to host.docker.internal timed out. (connect timeout=None)')\n       urllib3.exceptions.MaxRetryError: HTTPConnectionPool(host='host.docker.internal', port=5102): Max retries exceeded with url: /api/v1/Orders/ship (Caused by ConnectTimeoutError(<urllib3.connection.HTTPConnection object at 0x0000019F43C47E50>, 'Connection to host.docker.internal timed out. (connect timeout=None)'))\n               requests.exceptions.ConnectTimeout: HTTPConnectionPool(host='host.docker.internal', port=5102): Max retries exceeded with url: /api/v1/Orders/ship (Caused by ConnectTimeoutError(<urllib3.connection.HTTPConnection object at 0x0000019F43C47E50>, 'Connection to host.docker.internal timed out. (connect timeout=None)'))\n", "test_name": "test_ship_others_user_order", "rerun": "0"}, "4": {"status": "FAIL", "message": "   ValueError: substring not found\n", "test_name": "test_accessing_orders_unauthorized", "rerun": "0"}, "5": {"status": "FAIL", "message": "   ValueError: substring not found\n", "test_name": "test_accessing_get_order_by_id_unauthorized", "rerun": "0"}, "6": {"status": "FAIL", "message": "   ValueError: substring not found\n", "test_name": "test_accessing_card_types_unauthorized", "rerun": "0"}, "7": {"status": "FAIL", "message": "   ValueError: substring not found\n", "test_name": "test_accessing_ship_order_unauthorized", "rerun": "0"}, "8": {"status": "FAIL", "message": "   ValueError: substring not found\n", "test_name": "test_accessing_cancel_order_unauthorized", "rerun": "0"}}, "suite_name": "Tests/test_non_functional.py"}, "1": {"suite_name": "Tests/test_ordering_api.py", "tests": {"0": {"status": "PASS", "message": "", "test_name": "test_mss", "rerun": "0"}, "1": {"status": "FAIL", "message": "           TimeoutError: [WinError 10060] A connection attempt failed because the connected party did not properly respond after a period of time, or established connection failed because connected host has failed to respond\n       urllib3.exceptions.ConnectTimeoutError: (<urllib3.connection.HTTPConnection object at 0x0000019F43D52800>, 'Connection to host.docker.internal timed out. (connect timeout=None)')\n       urllib3.exceptions.MaxRetryError: HTTPConnectionPool(host='host.docker.internal', port=5102): Max retries exceeded with url: /api/v1/Orders (Caused by ConnectTimeoutError(<urllib3.connection.HTTPConnection object at 0x0000019F43D52800>, 'Connection to host.docker.internal timed out. (connect timeout=None)'))\n               requests.exceptions.ConnectTimeout: HTTPConnectionPool(host='host.docker.internal', port=5102): Max retries exceeded with url: /api/v1/Orders (Caused by ConnectTimeoutError(<urllib3.connection.HTTPConnection object at 0x0000019F43D52800>, 'Connection to host.docker.internal timed out. (connect timeout=None)'))\n", "test_name": "test_get_all_orders", "rerun": "0"}, "2": {"status": "FAIL", "message": "           TimeoutError: [WinError 10060] A connection attempt failed because the connected party did not properly respond after a period of time, or established connection failed because connected host has failed to respond\n       urllib3.exceptions.ConnectTimeoutError: (<urllib3.connection.HTTPConnection object at 0x0000019F43D8E920>, 'Connection to host.docker.internal timed out. (connect timeout=None)')\n       urllib3.exceptions.MaxRetryError: HTTPConnectionPool(host='host.docker.internal', port=5102): Max retries exceeded with url: /api/v1/orders/3 (Caused by ConnectTimeoutError(<urllib3.connection.HTTPConnection object at 0x0000019F43D8E920>, 'Connection to host.docker.internal timed out. (connect timeout=None)'))\n               requests.exceptions.ConnectTimeout: HTTPConnectionPool(host='host.docker.internal', port=5102): Max retries exceeded with url: /api/v1/orders/3 (Caused by ConnectTimeoutError(<urllib3.connection.HTTPConnection object at 0x0000019F43D8E920>, 'Connection to host.docker.internal timed out. (connect timeout=None)'))\n", "test_name": "test_get_order_by_id", "rerun": "0"}, "3": {"status": "FAIL", "message": "           TimeoutError: [WinError 10060] A connection attempt failed because the connected party did not properly respond after a period of time, or established connection failed because connected host has failed to respond\n       urllib3.exceptions.ConnectTimeoutError: (<urllib3.connection.HTTPConnection object at 0x0000019F43C45F60>, 'Connection to host.docker.internal timed out. (connect timeout=None)')\n       urllib3.exceptions.MaxRetryError: HTTPConnectionPool(host='host.docker.internal', port=5102): Max retries exceeded with url: /api/v1/orders/0 (Caused by ConnectTimeoutError(<urllib3.connection.HTTPConnection object at 0x0000019F43C45F60>, 'Connection to host.docker.internal timed out. (connect timeout=None)'))\n               requests.exceptions.ConnectTimeout: HTTPConnectionPool(host='host.docker.internal', port=5102): Max retries exceeded with url: /api/v1/orders/0 (Caused by ConnectTimeoutError(<urllib3.connection.HTTPConnection object at 0x0000019F43C45F60>, 'Connection to host.docker.internal timed out. (connect timeout=None)'))\n", "test_name": "test_negative_get_order_by_id", "rerun": "0"}, "4": {"status": "FAIL", "message": "           TimeoutError: [WinError 10060] A connection attempt failed because the connected party did not properly respond after a period of time, or established connection failed because connected host has failed to respond\n       urllib3.exceptions.ConnectTimeoutError: (<urllib3.connection.HTTPConnection object at 0x0000019F43C12C20>, 'Connection to host.docker.internal timed out. (connect timeout=None)')\n       urllib3.exceptions.MaxRetryError: HTTPConnectionPool(host='host.docker.internal', port=5102): Max retries exceeded with url: /api/v1/Orders/cardtypes (Caused by ConnectTimeoutError(<urllib3.connection.HTTPConnection object at 0x0000019F43C12C20>, 'Connection to host.docker.internal timed out. (connect timeout=None)'))\n               requests.exceptions.ConnectTimeout: HTTPConnectionPool(host='host.docker.internal', port=5102): Max retries exceeded with url: /api/v1/Orders/cardtypes (Caused by ConnectTimeoutError(<urllib3.connection.HTTPConnection object at 0x0000019F43C12C20>, 'Connection to host.docker.internal timed out. (connect timeout=None)'))\n", "test_name": "test_get_cardtypes", "rerun": "0"}, "5": {"status": "FAIL", "message": "           TimeoutError: [WinError 10060] A connection attempt failed because the connected party did not properly respond after a period of time, or established connection failed because connected host has failed to respond\n       urllib3.exceptions.ConnectTimeoutError: (<urllib3.connection.HTTPConnection object at 0x0000019F43C1FAF0>, 'Connection to host.docker.internal timed out. (connect timeout=None)')\n       urllib3.exceptions.MaxRetryError: HTTPConnectionPool(host='host.docker.internal', port=5102): Max retries exceeded with url: /api/v1/Orders/cancel (Caused by ConnectTimeoutError(<urllib3.connection.HTTPConnection object at 0x0000019F43C1FAF0>, 'Connection to host.docker.internal timed out. (connect timeout=None)'))\n               requests.exceptions.ConnectTimeout: HTTPConnectionPool(host='host.docker.internal', port=5102): Max retries exceeded with url: /api/v1/Orders/cancel (Caused by ConnectTimeoutError(<urllib3.connection.HTTPConnection object at 0x0000019F43C1FAF0>, 'Connection to host.docker.internal timed out. (connect timeout=None)'))\n", "test_name": "test_cancel_submitted_order", "rerun": "0"}, "6": {"status": "FAIL", "message": "           TimeoutError: [WinError 10060] A connection attempt failed because the connected party did not properly respond after a period of time, or established connection failed because connected host has failed to respond\n       urllib3.exceptions.ConnectTimeoutError: (<urllib3.connection.HTTPConnection object at 0x0000019F43CA6860>, 'Connection to host.docker.internal timed out. (connect timeout=None)')\n       urllib3.exceptions.MaxRetryError: HTTPConnectionPool(host='host.docker.internal', port=5102): Max retries exceeded with url: /api/v1/Orders/cancel (Caused by ConnectTimeoutError(<urllib3.connection.HTTPConnection object at 0x0000019F43CA6860>, 'Connection to host.docker.internal timed out. (connect timeout=None)'))\n               requests.exceptions.ConnectTimeout: HTTPConnectionPool(host='host.docker.internal', port=5102): Max retries exceeded with url: /api/v1/Orders/cancel (Caused by ConnectTimeoutError(<urllib3.connection.HTTPConnection object at 0x0000019F43CA6860>, 'Connection to host.docker.internal timed out. (connect timeout=None)'))\n", "test_name": "test_cancel_awaitingvalidation_order", "rerun": "0"}, "7": {"status": "FAIL", "message": "           TimeoutError: [WinError 10060] A connection attempt failed because the connected party did not properly respond after a period of time, or established connection failed because connected host has failed to respond\n       urllib3.exceptions.ConnectTimeoutError: (<urllib3.connection.HTTPConnection object at 0x0000019F437A72B0>, 'Connection to host.docker.internal timed out. (connect timeout=None)')\n       urllib3.exceptions.MaxRetryError: HTTPConnectionPool(host='host.docker.internal', port=5102): Max retries exceeded with url: /api/v1/Orders/cancel (Caused by ConnectTimeoutError(<urllib3.connection.HTTPConnection object at 0x0000019F437A72B0>, 'Connection to host.docker.internal timed out. (connect timeout=None)'))\n               requests.exceptions.ConnectTimeout: HTTPConnectionPool(host='host.docker.internal', port=5102): Max retries exceeded with url: /api/v1/Orders/cancel (Caused by ConnectTimeoutError(<urllib3.connection.HTTPConnection object at 0x0000019F437A72B0>, 'Connection to host.docker.internal timed out. (connect timeout=None)'))\n", "test_name": "test_cancel_stockconfirmed_order", "rerun": "0"}, "8": {"status": "FAIL", "message": "           TimeoutError: [WinError 10060] A connection attempt failed because the connected party did not properly respond after a period of time, or established connection failed because connected host has failed to respond\n       urllib3.exceptions.ConnectTimeoutError: (<urllib3.connection.HTTPConnection object at 0x0000019F43C10E50>, 'Connection to host.docker.internal timed out. (connect timeout=None)')\n       urllib3.exceptions.MaxRetryError: HTTPConnectionPool(host='host.docker.internal', port=5102): Max retries exceeded with url: /api/v1/Orders/cancel (Caused by ConnectTimeoutError(<urllib3.connection.HTTPConnection object at 0x0000019F43C10E50>, 'Connection to host.docker.internal timed out. (connect timeout=None)'))\n               requests.exceptions.ConnectTimeout: HTTPConnectionPool(host='host.docker.internal', port=5102): Max retries exceeded with url: /api/v1/Orders/cancel (Caused by ConnectTimeoutError(<urllib3.connection.HTTPConnection object at 0x0000019F43C10E50>, 'Connection to host.docker.internal timed out. (connect timeout=None)'))\n", "test_name": "test_negative_cancel_order_after_payment", "rerun": "0"}, "9": {"status": "FAIL", "message": "           TimeoutError: [WinError 10060] A connection attempt failed because the connected party did not properly respond after a period of time, or established connection failed because connected host has failed to respond\n       urllib3.exceptions.ConnectTimeoutError: (<urllib3.connection.HTTPConnection object at 0x0000019F438D4730>, 'Connection to host.docker.internal timed out. (connect timeout=None)')\n       urllib3.exceptions.MaxRetryError: HTTPConnectionPool(host='host.docker.internal', port=5102): Max retries exceeded with url: /api/v1/Orders/ship (Caused by ConnectTimeoutError(<urllib3.connection.HTTPConnection object at 0x0000019F438D4730>, 'Connection to host.docker.internal timed out. (connect timeout=None)'))\n               requests.exceptions.ConnectTimeout: HTTPConnectionPool(host='host.docker.internal', port=5102): Max retries exceeded with url: /api/v1/Orders/ship (Caused by ConnectTimeoutError(<urllib3.connection.HTTPConnection object at 0x0000019F438D4730>, 'Connection to host.docker.internal timed out. (connect timeout=None)'))\n", "test_name": "test_ship_paid_order", "rerun": "0"}, "10": {"status": "FAIL", "message": "           TimeoutError: [WinError 10060] A connection attempt failed because the connected party did not properly respond after a period of time, or established connection failed because connected host has failed to respond\n       urllib3.exceptions.ConnectTimeoutError: (<urllib3.connection.HTTPConnection object at 0x0000019F437DE5F0>, 'Connection to host.docker.internal timed out. (connect timeout=None)')\n       urllib3.exceptions.MaxRetryError: HTTPConnectionPool(host='host.docker.internal', port=5102): Max retries exceeded with url: /api/v1/Orders/ship (Caused by ConnectTimeoutError(<urllib3.connection.HTTPConnection object at 0x0000019F437DE5F0>, 'Connection to host.docker.internal timed out. (connect timeout=None)'))\n               requests.exceptions.ConnectTimeout: HTTPConnectionPool(host='host.docker.internal', port=5102): Max retries exceeded with url: /api/v1/Orders/ship (Caused by ConnectTimeoutError(<urllib3.connection.HTTPConnection object at 0x0000019F437DE5F0>, 'Connection to host.docker.internal timed out. (connect timeout=None)'))\n", "test_name": "test_negative_ship_order", "rerun": "0"}}, "status": {"total_pass": 1, "total_skip": 0, "total_xpass": 0, "total_xfail": 0, "total_rerun": 0, "total_fail": 10, "total_error": 0}}, "2": {"suite_name": "Tests/test_ordering_service.py", "tests": {"0": {"status": "FAIL", "message": "   KeyError: 'eshop/ordering.backgroundtasks:linux-latest'\n", "test_name": "test_mss", "rerun": "0"}, "1": {"status": "FAIL", "message": "   KeyError: 'eshop/ordering.backgroundtasks:linux-latest'\n", "test_name": "test_ordering_items_outOfStock", "rerun": "0"}, "2": {"status": "FAIL", "message": "   KeyError: 'eshop/ordering.backgroundtasks:linux-latest'\n", "test_name": "test_ordering_with_invalid_payment", "rerun": "0"}}, "status": {"total_pass": 0, "total_skip": 0, "total_xpass": 0, "total_xfail": 0, "total_rerun": 0, "total_fail": 3, "total_error": 0}}}}, "date": "March 19, 2023", "start_time": 1679206826.262345, "total_suite": 3, "status": "FAIL", "status_list": {"pass": "2", "fail": "21", "skip": "0", "error": "0", "xpass": "0", "xfail": "0", "rerun": "0"}, "total_tests": "23"}